Workbook

Sheet raw data (30 Apr '25)
B1: 45777
B2: raw data
B4: raw data
B5: [per 2mm] | C5: [A/B/C] | D5: [V] | E5: [A]
A6: # | B6: throttle | C6: load | D6: Voltage-M | E6: Current-M
A7: 1 | B7: 1 | C7: A | D7: 17.2 | E7: 8.6
B8: 1 | C8: A | D8: 16.7 | E8: 9
B9: 1 | C9: A | D9: 16.5 | E9: 8.8
B10: 1 | C10: A | D10: 16.4 | E10: 8.8
B11: 1 | C11: A | D11: 16.6 | E11: 8.1
A13: 2 | B13: 2 | C13: A | D13: 23.5 | E13: 18.1
B14: 2 | C14: A | D14: 23.6 | E14: 18.7
B15: 2 | C15: A | D15: 23.5 | E15: 19.1
B16: 2 | C16: A | D16: 23.4 | E16: 19.9
B17: 2 | C17: A | D17: 23.4 | E17: 20.3
B18: 2 | C18: A | D18: 23.5 | E18: 20.5
B19: 2 | C19: A | D19: 23.3 | E19: 20.7
B20: 2 | C20: A | D20: 23.6 | E20: 21.3
A22: 3 | B22: 3 | C22: A | D22: 30.2 | E22: 26
B23: 3 | C23: A | D23: 30.3 | E23: 25.8
B24: 3 | C24: A | D24: 30.2 | E24: 25.6
B25: 3 | C25: A | D25: 30.3 | E25: 25.6
B26: 3 | C26: A | D26: 30.2 | E26: 25.4
B27: 3 | C27: A | D27: 30.3 | E27: 25.2
B28: 3 | C28: A | D28: 30.2 | E28: 25.4
B29: 3 | C29: A | D29: 30.2 | E29: 25.2
B30: 3 | C30: A | D30: 30.3 | E30: 25.4
A32: 4 | B32: 4 | C32: A | D32: 33 | E32: 26
A34: 5 | B34: 4 | C34: AB | D34: 31.5 | E34: 53
B35: 4 | C35: AB | D35: 30.9 | E35: 52.8
B36: 4 | C36: AB | D36: 30.9 | E36: 51.6
B37: 4 | C37: AB | D37: 31.3 | E37: 50.2
B38: 4 | C38: AB | D38: 31.8 | E38: 48.5
B39: 4 | C39: AB | D39: 31.8 | E39: 48.1
B40: 4 | C40: AB | D40: 31.5 | E40: 48.9
B41: 4 | C41: AB | D41: 32 | E41: 48.9
B42: 4 | C42: AB | D42: 32 | E42: 48.5
A44: 6 | B44: 3 | C44: AB | D44: 26 | E44: 49.1
B45: 3 | C45: AB | D45: 26.2 | E45: 49.1
B46: 3 | C46: AB | D46: 26.2 | E46: 49.1
...

Sheet agni eff
A1: AGNI EFFICIENCY
A2: volt/current | B2: 12 | C2: 15.8 | D2: 16.4 | E2: 16.5 | F2: 17.4 | G2: 17.5 | H2: 18.6 | I2: 20.2 | J2: 20.4 | K2: 20.7 | L2: 20.9 | M2: 23 | N2: 23.5 | O2: 24 | P2: 26.2 | Q2: 28.1 | R2: 28.9 | S2: 30 | T2: 30.2 | U2: 31.5 | V2: 32.8 | W2: 33 | X2: 33.7 | Y2: 34.4 | Z2: 36 | AA2: 37.1 | AB2: 48 | AE2: voltage
A3: 0 | B3: 0 | C3: 0 | D3: 0 | E3: 0 | F3: 0 | G3: 0 | H3: 0 | I3: 0 | J3: 0 | K3: 0 | L3: 0 | M3: 0 | N3: 0 | O3: 0 | P3: 0 | Q3: 0 | R3: 0 | S3: 0 | T3: 0 | U3: 0 | V3: 0 | W3: 0 | X3: 0 | Y3: 0 | Z3: 0 | AA3: 0 | AB3: 0 | AD3: current | AE3: 12 | AF3: 24 | AG3: 36
A4: 0.38 | B4: =B$3+(B$9-B$3)/($A$9-$A$3)*($A4-$A$3) -> 0.01786 | C4: =C$3+(C$9-C$3)/($A$9-$A$3)*($A4-$A$3) -> 0.017980333 | D4: =D$3+(D$9-D$3)/($A$9-$A$3)*($A4-$A$3) -> 0.017999333 | E4: =E$3+(E$9-E$3)/($A$9-$A$3)*($A4-$A$3) -> 0.0180025 | F4: =F$3+(F$9-F$3)/($A$9-$A$3)*($A4-$A$3) -> 0.018031 | G4: =G$3+(G$9-G$3)/($A$9-$A$3)*($A4-$A$3) -> 0.018034167 | H4: =H$3+(H$9-H$3)/($A$9-$A$3)*($A4-$A$3) -> 0.018069 | I4: =I$3+(I$9-I$3)/($A$9-$A$3)*($A4-$A$3) -> 0.018119667 | ... Z4: =Z$3+(Z$9-Z$3)/($A$9-$A$3)*($A4-$A$3) -> 0.01425 | AD4: 10 | AE4: =47% -> 0.47 | AF4: =48% -> 0.48 | AG4: =37.5% -> 0.375
A5: 0.58 | B5: =B$3+(B$9-B$3)/($A$9-$A$3)*($A5-$A$3) -> 0.02726 | C5: =C$3+(C$9-C$3)/($A$9-$A$3)*($A5-$A$3) -> 0.027443667 | D5: =D$3+(D$9-D$3)/($A$9-$A$3)*($A5-$A$3) -> 0.027472667 | E5: =E$3+(E$9-E$3)/($A$9-$A$3)*($A5-$A$3) -> 0.0274775 | F5: =F$3+(F$9-F$3)/($A$9-$A$3)*($A5-$A$3) -> 0.027521 | G5: =G$3+(G$9-G$3)/($A$9-$A$3)*($A5-$A$3) -> 0.027525833 | H5: =H$3+(H$9-H$3)/($A$9-$A$3)*($A5-$A$3) -> 0.027579 | I5: =I$3+(I$9-I$3)/($A$9-$A$3)*($A5-$A$3) -> 0.027656333 | ... Z5: =Z$3+(Z$9-Z$3)/($A$9-$A$3)*($A5-$A$3) -> 0.02175 | AD5: 20 | AE5: =71% -> 0.71 | AF5: =74.5% -> 0.745 | AG5: =64.5% -> 0.645
A6: 8.6 | B6: =B$3+(B$9-B$3)/($A$9-$A$3)*($A6-$A$3) -> 0.4042 | C6: =C$3+(C$9-C$3)/($A$9-$A$3)*($A6-$A$3) -> 0.40692333 | D6: =D$3+(D$9-D$3)/($A$9-$A$3)*($A6-$A$3) -> 0.40735333 | E6: =E$3+(E$9-E$3)/($A$9-$A$3)*($A6-$A$3) -> 0.407425 | F6: =F$3+(F$9-F$3)/($A$9-$A$3)*($A6-$A$3) -> 0.40807 | G6: =G$3+(G$9-G$3)/($A$9-$A$3)*($A6-$A$3) -> 0.40814167 | H6: =H$3+(H$9-H$3)/($A$9-$A$3)*($A6-$A$3) -> 0.40893 | I6: =I$3+(I$9-I$3)/($A$9-$A$3)*($A6-$A$3) -> 0.41007667 | ... Z6: =Z$3+(Z$9-Z$3)/($A$9-$A$3)*($A6-$A$3) -> 0.3225 | AD6: 30 | AE6: =81.5% -> 0.815 | AF6: =83.5% -> 0.835 | AG6: =73.8% -> 0.738
A7: 8.8 | B7: =B$3+(B$9-B$3)/($A$9-$A$3)*($A7-$A$3) -> 0.4136 | C7: =C$3+(C$9-C$3)/($A$9-$A$3)*($A7-$A$3) -> 0.41638667 | D7: =D$3+(D$9-D$3)/($A$9-$A$3)*($A7-$A$3) -> 0.41682667 | E7: =E$3+(E$9-E$3)/($A$9-$A$3)*($A7-$A$3) -> 0.4169 | F7: =F$3+(F$9-F$3)/($A$9-$A$3)*($A7-$A$3) -> 0.41756 | G7: =G$3+(G$9-G$3)/($A$9-$A$3)*($A7-$A$3) -> 0.41763333 | H7: =H$3+(H$9-H$3)/($A$9-$A$3)*($A7-$A$3) -> 0.41844 | I7: =I$3+(I$9-I$3)/($A$9-$A$3)*($A7-$A$3) -> 0.41961333 | ... Z7: =Z$3+(Z$9-Z$3)/($A$9-$A$3)*($A7-$A$3) -> 0.33 | AD7: 40 | AE7: =84% -> 0.84 | AF7: =87.5% -> 0.875 | AG7: =79.2% -> 0.792
A8: 9.6 | B8: =B$3+(B$9-B$3)/($A$9-$A$3)*($A8-$A$3) -> 0.4512 | C8: =C$3+(C$9-C$3)/($A$9-$A$3)*($A8-$A$3) -> 0.45424 | D8: =D$3+(D$9-D$3)/($A$9-$A$3)*($A8-$A$3) -> 0.45472 | E8: =E$3+(E$9-E$3)/($A$9-$A$3)*($A8-$A$3) -> 0.4548 | F8: =F$3+(F$9-F$3)/($A$9-$A$3)*($A8-$A$3) -> 0.45552 | G8: =G$3+(G$9-G$3)/($A$9-$A$3)*($A8-$A$3) -> 0.4556 | H8: =H$3+(H$9-H$3)/($A$9-$A$3)*($A8-$A$3) -> 0.45648 | I8: =I$3+(I$9-I$3)/($A$9-$A$3)*($A8-$A$3) -> 0.45776 | ... Z8: =Z$3+(Z$9-Z$3)/($A$9-$A$3)*($A8-$A$3) -> 0.36 | AD8: 50 | AE8: =85% -> 0.85 | AF8: =90% -> 0.9 | AG8: =82.5% -> 0.825
A9: 10 | B9: =47% -> 0.47 | C9: =$B9+(($O9-$B9)/($O$2-$B$2))*(C$2-$B$2) -> 0.47316667 | D9: =$B9+(($O9-$B9)/($O$2-$B$2))*(D$2-$B$2) -> 0.47366667 | E9: =$B9+(($O9-$B9)/($O$2-$B$2))*(E$2-$B$2) -> 0.47375 | F9: =$B9+(($O9-$B9)/($O$2-$B$2))*(F$2-$B$2) -> 0.4745 | G9: =$B9+(($O9-$B9)/($O$2-$B$2))*(G$2-$B$2) -> 0.47458333 | H9: =$B9+(($O9-$B9)/($O$2-$B$2))*(H$2-$B$2) -> 0.4755 | I9: =$B9+(($O9-$B9)/($O$2-$B$2))*(I$2-$B$2) -> 0.47683333 | J9: =$B9+(($O9-$B9)/($O$2-$B$2))*(J$2-$B$2) -> 0.477 | ... N9: =$B9+(($O9-$B9)/($O$2-$B$2))*(N$2-$B$2) -> 0.47958333 | O9: =48% -> 0.48 | P9: =$O9+(($Z9-$O9)/($Z$2-$O$2))*(P$2-$O$2) -> 0.46075 | Q9: =$O9+(($Z9-$O9)/($Z$2-$O$2))*(Q$2-$O$2) -> 0.444125 | R9: =$O9+(($Z9-$O9)/($Z$2-$O$2))*(R$2-$O$2) -> 0.437125 | S9: =$O9+(($Z9-$O9)/($Z$2-$O$2))*(S$2-$O$2) -> 0.4275 | T9: =$O9+(($Z9-$O9)/($Z$2-$O$2))*(T$2-$O$2) -> 0.42575 | U9: =$O9+(($Z9-$O9)/($Z$2-$O$2))*(U$2-$O$2) -> 0.414375 | V9: =$O9+(($Z9-$O9)/($Z$2-$O$2))*(V$2-$O$2) -> 0.403 | W9: =$O9+(($Z9-$O9)/($Z$2-$O$2))*(W$2-$O$2) -> 0.40125 | ... Y9: =$O9+(($Z9-$O9)/($Z$2-$O$2))*(Y$2-$O$2) -> 0.389 | Z9: =37.5% -> 0.375 | AD9: 60 | AE9: =85.8% -> 0.858 | AF9: =90.7% -> 0.907 | AG9: =84.6% -> 0.846
A10: 11 | B10: =B$9+(B$14-B$9)/($A$14-$A$9)*($A10-$A$9) -> 0.494 | C10: =C$9+(C$14-C$9)/($A$14-$A$9)*($A10-$A$9) -> 0.49795833 | D10: =D$9+(D$14-D$9)/($A$14-$A$9)*($A10-$A$9) -> 0.49858333 | E10: =E$9+(E$14-E$9)/($A$14-$A$9)*($A10-$A$9) -> 0.4986875 | F10: =F$9+(F$14-F$9)/($A$14-$A$9)*($A10-$A$9) -> 0.499625 | G10: =G$9+(G$14-G$9)/($A$14-$A$9)*($A10-$A$9) -> 0.49972917 | H10: =H$9+(H$14-H$9)/($A$14-$A$9)*($A10-$A$9) -> 0.500875 | I10: =I$9+(I$14-I$9)/($A$14-$A$9)*($A10-$A$9) -> 0.50254167 | ... Z10: =Z$9+(Z$14-Z$9)/($A$14-$A$9)*($A10-$A$9) -> 0.402 | AD10: 70 | AE10: =86% -> 0.86 | AF10: =91% -> 0.91 | AG10: =86.2% -> 0.862
A11: 11.8 | B11: =B$9+(B$14-B$9)/($A$14-$A$9)*($A11-$A$9) -> 0.5132 | C11: =C$9+(C$14-C$9)/($A$14-$A$9)*($A11-$A$9) -> 0.51779167 | D11: =D$9+(D$14-D$9)/($A$14-$A$9)*($A11-$A$9) -> 0.51851667 | E11: =E$9+(E$14-E$9)/($A$14-$A$9)*($A11-$A$9) -> 0.5186375 | F11: =F$9+(F$14-F$9)/($A$14-$A$9)*($A11-$A$9) -> 0.519725 | G11: =G$9+(G$14-G$9)/($A$14-$A$9)*($A11-$A$9) -> 0.51984583 | H11: =H$9+(H$14-H$9)/($A$14-$A$9)*($A11-$A$9) -> 0.521175 | I11: =I$9+(I$14-I$9)/($A$14-$A$9)*($A11-$A$9) -> 0.52310833 | ... Z11: =Z$9+(Z$14-Z$9)/($A$14-$A$9)*($A11-$A$9) -> 0.4236 | AD11: 80 | AE11: =86.1% -> 0.861 | AF11: =91.1% -> 0.911 | AG11: =87.6% -> 0.876
A12: 12.7 | B12: =B$9+(B$14-B$9)/($A$14-$A$9)*($A12-$A$9) -> 0.5348 | C12: =C$9+(C$14-C$9)/($A$14-$A$9)*($A12-$A$9) -> 0.54010417 | D12: =D$9+(D$14-D$9)/($A$14-$A$9)*($A12-$A$9) -> 0.54094167 | E12: =E$9+(E$14-E$9)/($A$14-$A$9)*($A12-$A$9) -> 0.54108125 | F12: =F$9+(F$14-F$9)/($A$14-$A$9)*($A12-$A$9) -> 0.5423375 | G12: =G$9+(G$14-G$9)/($A$14-$A$9)*($A12-$A$9) -> 0.54247708 | H12: =H$9+(H$14-H$9)/($A$14-$A$9)*($A12-$A$9) -> 0.5440125 | I12: =I$9+(I$14-I$9)/($A$14-$A$9)*($A12-$A$9) -> 0.54624583 | ... Z12: =Z$9+(Z$14-Z$9)/($A$14-$A$9)*($A12-$A$9) -> 0.4479 | AD12: 90 | AE12: =86.1% -> 0.861 | AF12: =91.1% -> 0.911 | AG12: =88.7% -> 0.887
A13: 12.9 | B13: =B$9+(B$14-B$9)/($A$14-$A$9)*($A13-$A$9) -> 0.5396 | C13: =C$9+(C$14-C$9)/($A$14-$A$9)*($A13-$A$9) -> 0.5450625 | D13: =D$9+(D$14-D$9)/($A$14-$A$9)*($A13-$A$9) -> 0.545925 | E13: =E$9+(E$14-E$9)/($A$14-$A$9)*($A13-$A$9) -> 0.54606875 | F13: =F$9+(F$14-F$9)/($A$14-$A$9)*($A13-$A$9) -> 0.5473625 | G13: =G$9+(G$14-G$9)/($A$14-$A$9)*($A13-$A$9) -> 0.54750625 | H13: =H$9+(H$14-H$9)/($A$14-$A$9)*($A13-$A$9) -> 0.5490875 | I13: =I$9+(I$14-I$9)/($A$14-$A$9)*($A13-$A$9) -> 0.5513875 | ... Z13: =Z$9+(Z$14-Z$9)/($A$14-$A$9)*($A13-$A$9) -> 0.4533 | AD13: 100 | AE13: =86% -> 0.86 | AF13: =91% -> 0.91 | AG13: =89.7% -> 0.897
A14: 20 | B14: =71% -> 0.71 | C14: =$B14+(($O14-$B14)/($O$2-$B$2))*(C$2-$B$2) -> 0.72108333 | D14: =$B14+(($O14-$B14)/($O$2-$B$2))*(D$2-$B$2) -> 0.72283333 | E14: =$B14+(($O14-$B14)/($O$2-$B$2))*(E$2-$B$2) -> 0.723125 | F14: =$B14+(($O14-$B14)/($O$2-$B$2))*(F$2-$B$2) -> 0.72575 | G14: =$B14+(($O14-$B14)/($O$2-$B$2))*(G$2-$B$2) -> 0.72604167 | H14: =$B14+(($O14-$B14)/($O$2-$B$2))*(H$2-$B$2) -> 0.72925 | I14: =$B14+(($O14-$B14)/($O$2-$B$2))*(I$2-$B$2) -> 0.73391667 | J14: =$B14+(($O14-$B14)/($O$2-$B$2))*(J$2-$B$2) -> 0.7345 | ... N14: =$B14+(($O14-$B14)/($O$2-$B$2))*(N$2-$B$2) -> 0.74354167 | O14: =74.5% -> 0.745 | P14: =$O14+(($Z14-$O14)/($Z$2-$O$2))*(P$2-$O$2) -> 0.72666667 | Q14: =$O14+(($Z14-$O14)/($Z$2-$O$2))*(Q$2-$O$2) -> 0.71083333 | R14: =$O14+(($Z14-$O14)/($Z$2-$O$2))*(R$2-$O$2) -> 0.70416667 | S14: =$O14+(($Z14-$O14)/($Z$2-$O$2))*(S$2-$O$2) -> 0.695 | T14: =$O14+(($Z14-$O14)/($Z$2-$O$2))*(T$2-$O$2) -> 0.69333333 | U14: =$O14+(($Z14-$O14)/($Z$2-$O$2))*(U$2-$O$2) -> 0.6825 | V14: =$O14+(($Z14-$O14)/($Z$2-$O$2))*(V$2-$O$2) -> 0.67166667 | W14: =$O14+(($Z14-$O14)/($Z$2-$O$2))*(W$2-$O$2) -> 0.67 | ... Y14: =$O14+(($Z14-$O14)/($Z$2-$O$2))*(Y$2-$O$2) -> 0.65833333 | Z14: =64.5% -> 0.645
A15: 20.5 | B15: =B$14+(B$22-B$14)/($A$22-$A$14)*($A15-$A$14) -> 0.71525 | C15: =C$14+(C$22-C$14)/($A$22-$A$14)*($A15-$A$14) -> 0.72609583 | D15: =D$14+(D$22-D$14)/($A$22-$A$14)*($A15-$A$14) -> 0.72780833 | E15: =E$14+(E$22-E$14)/($A$22-$A$14)*($A15-$A$14) -> 0.72809375 | F15: =F$14+(F$22-F$14)/($A$22-$A$14)*($A15-$A$14) -> 0.7306625 | G15: =G$14+(G$22-G$14)/($A$22-$A$14)*($A15-$A$14) -> 0.73094792 | H15: =H$14+(H$22-H$14)/($A$22-$A$14)*($A15-$A$14) -> 0.7340875 | I15: =I$14+(I$22-I$14)/($A$22-$A$14)*($A15-$A$14) -> 0.73865417 | ... Z15: =Z$14+(Z$22-Z$14)/($A$22-$A$14)*($A15-$A$14) -> 0.64965
A16: 20.9 | B16: =B$14+(B$22-B$14)/($A$22-$A$14)*($A16-$A$14) -> 0.71945 | C16: =C$14+(C$22-C$14)/($A$22-$A$14)*($A16-$A$14) -> 0.73010583 | D16: =D$14+(D$22-D$14)/($A$22-$A$14)*($A16-$A$14) -> 0.73178833 | E16: =E$14+(E$22-E$14)/($A$22-$A$14)*($A16-$A$14) -> 0.73206875 | F16: =F$14+(F$22-F$14)/($A$22-$A$14)*($A16-$A$14) -> 0.7345925 | G16: =G$14+(G$22-G$14)/($A$22-$A$14)*($A16-$A$14) -> 0.73487292 | H16: =H$14+(H$22-H$14)/($A$22-$A$14)*($A16-$A$14) -> 0.7379575 | I16: =I$14+(I$22-I$14)/($A$22-$A$14)*($A16-$A$14) -> 0.74244417 | ... Z16: =Z$14+(Z$22-Z$14)/($A$22-$A$14)*($A16-$A$14) -> 0.65337
A17: 21.1 | B17: =B$14+(B$22-B$14)/($A$22-$A$14)*($A17-$A$14) -> 0.72155 | C17: =C$14+(C$22-C$14)/($A$22-$A$14)*($A17-$A$14) -> 0.73211083 | D17: =D$14+(D$22-D$14)/($A$22-$A$14)*($A17-$A$14) -> 0.73377833 | E17: =E$14+(E$22-E$14)/($A$22-$A$14)*($A17-$A$14) -> 0.73405625 | F17: =F$14+(F$22-F$14)/($A$22-$A$14)*($A17-$A$14) -> 0.7365575 | G17: =G$14+(G$22-G$14)/($A$22-$A$14)*($A17-$A$14) -> 0.73683542 | H17: =H$14+(H$22-H$14)/($A$22-$A$14)*($A17-$A$14) -> 0.7398925 | I17: =I$14+(I$22-I$14)/($A$22-$A$14)*($A17-$A$14) -> 0.74433917 | ... Z17: =Z$14+(Z$22-Z$14)/($A$22-$A$14)*($A17-$A$14) -> 0.65523
A18: 22.7 | B18: =B$14+(B$22-B$14)/($A$22-$A$14)*($A18-$A$14) -> 0.73835 | C18: =C$14+(C$22-C$14)/($A$22-$A$14)*($A18-$A$14) -> 0.74815083 | D18: =D$14+(D$22-D$14)/($A$22-$A$14)*($A18-$A$14) -> 0.74969833 | E18: =E$14+(E$22-E$14)/($A$22-$A$14)*($A18-$A$14) -> 0.74995625 | F18: =F$14+(F$22-F$14)/($A$22-$A$14)*($A18-$A$14) -> 0.7522775 | G18: =G$14+(G$22-G$14)/($A$22-$A$14)*($A18-$A$14) -> 0.75253542 | H18: =H$14+(H$22-H$14)/($A$22-$A$14)*($A18-$A$14) -> 0.7553725 | I18: =I$14+(I$22-I$14)/($A$22-$A$14)*($A18-$A$14) -> 0.75949917 | ... Z18: =Z$14+(Z$22-Z$14)/($A$22-$A$14)*($A18-$A$14) -> 0.67011
A19: 25.4 | B19: =B$14+(B$22-B$14)/($A$22-$A$14)*($A19-$A$14) -> 0.7667 | C19: =C$14+(C$22-C$14)/($A$22-$A$14)*($A19-$A$14) -> 0.77521833 | D19: =D$14+(D$22-D$14)/($A$22-$A$14)*($A19-$A$14) -> 0.77656333 | E19: =E$14+(E$22-E$14)/($A$22-$A$14)*($A19-$A$14) -> 0.7767875 | F19: =F$14+(F$22-F$14)/($A$22-$A$14)*($A19-$A$14) -> 0.778805 | G19: =G$14+(G$22-G$14)/($A$22-$A$14)*($A19-$A$14) -> 0.77902917 | H19: =H$14+(H$22-H$14)/($A$22-$A$14)*($A19-$A$14) -> 0.781495 | I19: =I$14+(I$22-I$14)/($A$22-$A$14)*($A19-$A$14) -> 0.78508167 | ... Z19: =Z$14+(Z$22-Z$14)/($A$22-$A$14)*($A19-$A$14) -> 0.69522
A20: 26 | B20: =B$14+(B$22-B$14)/($A$22-$A$14)*($A20-$A$14) -> 0.773 | C20: =C$14+(C$22-C$14)/($A$22-$A$14)*($A20-$A$14) -> 0.78123333 | D20: =D$14+(D$22-D$14)/($A$22-$A$14)*($A20-$A$14) -> 0.78253333 | E20: =E$14+(E$22-E$14)/($A$22-$A$14)*($A20-$A$14) -> 0.78275 | F20: =F$14+(F$22-F$14)/($A$22-$A$14)*($A20-$A$14) -> 0.7847 | G20: =G$14+(G$22-G$14)/($A$22-$A$14)*($A20-$A$14) -> 0.78491667 | H20: =H$14+(H$22-H$14)/($A$22-$A$14)*($A20-$A$14) -> 0.7873 | I20: =I$14+(I$22-I$14)/($A$22-$A$14)*($A20-$A$14) -> 0.79076667 | ... Z20: =Z$14+(Z$22-Z$14)/($A$22-$A$14)*($A20-$A$14) -> 0.7008
A21: 28.6 | B21: =B$14+(B$22-B$14)/($A$22-$A$14)*($A21-$A$14) -> 0.8003 | C21: =C$14+(C$22-C$14)/($A$22-$A$14)*($A21-$A$14) -> 0.80729833 | D21: =D$14+(D$22-D$14)/($A$22-$A$14)*($A21-$A$14) -> 0.80840333 | E21: =E$14+(E$22-E$14)/($A$22-$A$14)*($A21-$A$14) -> 0.8085875 | F21: =F$14+(F$22-F$14)/($A$22-$A$14)*($A21-$A$14) -> 0.810245 | G21: =G$14+(G$22-G$14)/($A$22-$A$14)*($A21-$A$14) -> 0.81042917 | H21: =H$14+(H$22-H$14)/($A$22-$A$14)*($A21-$A$14) -> 0.812455 | I21: =I$14+(I$22-I$14)/($A$22-$A$14)*($A21-$A$14) -> 0.81540167 | ... Z21: =Z$14+(Z$22-Z$14)/($A$22-$A$14)*($A21-$A$14) -> 0.72498
A22: 30 | B22: =81.5% -> 0.815 | C22: =$B22+(($O22-$B22)/($O$2-$B$2))*(C$2-$B$2) -> 0.82133333 | D22: =$B22+(($O22-$B22)/($O$2-$B$2))*(D$2-$B$2) -> 0.82233333 | E22: =$B22+(($O22-$B22)/($O$2-$B$2))*(E$2-$B$2) -> 0.8225 | F22: =$B22+(($O22-$B22)/($O$2-$B$2))*(F$2-$B$2) -> 0.824 | G22: =$B22+(($O22-$B22)/($O$2-$B$2))*(G$2-$B$2) -> 0.82416667 | H22: =$B22+(($O22-$B22)/($O$2-$B$2))*(H$2-$B$2) -> 0.826 | I22: =$B22+(($O22-$B22)/($O$2-$B$2))*(I$2-$B$2) -> 0.82866667 | J22: =$B22+(($O22-$B22)/($O$2-$B$2))*(J$2-$B$2) -> 0.829 | ... N22: =$B22+(($O22-$B22)/($O$2-$B$2))*(N$2-$B$2) -> 0.83416667 | O22: =83.5% -> 0.835 | P22: =$O22+(($Z22-$O22)/($Z$2-$O$2))*(P$2-$O$2) -> 0.81721667 | Q22: =$O22+(($Z22-$O22)/($Z$2-$O$2))*(Q$2-$O$2) -> 0.80185833 | R22: =$O22+(($Z22-$O22)/($Z$2-$O$2))*(R$2-$O$2) -> 0.79539167 | S22: =$O22+(($Z22-$O22)/($Z$2-$O$2))*(S$2-$O$2) -> 0.7865 | T22: =$O22+(($Z22-$O22)/($Z$2-$O$2))*(T$2-$O$2) -> 0.78488333 | U22: =$O22+(($Z22-$O22)/($Z$2-$O$2))*(U$2-$O$2) -> 0.774375 | V22: =$O22+(($Z22-$O22)/($Z$2-$O$2))*(V$2-$O$2) -> 0.76386667 | W22: =$O22+(($Z22-$O22)/($Z$2-$O$2))*(W$2-$O$2) -> 0.76225 | ... Y22: =$O22+(($Z22-$O22)/($Z$2-$O$2))*(Y$2-$O$2) -> 0.75093333 | Z22: =73.8% -> 0.738 | AB22: 0.7
A23: 32.8 | B23: =B$22+(B$28-B$22)/($A$28-$A$22)*($A23-$A$22) -> 0.822 | C23: =C$22+(C$28-C$22)/($A$28-$A$22)*($A23-$A$22) -> 0.82966333 | D23: =D$22+(D$28-D$22)/($A$28-$A$22)*($A23-$A$22) -> 0.83087333 | E23: =E$22+(E$28-E$22)/($A$28-$A$22)*($A23-$A$22) -> 0.831075 | F23: =F$22+(F$28-F$22)/($A$28-$A$22)*($A23-$A$22) -> 0.83289 | G23: =G$22+(G$28-G$22)/($A$28-$A$22)*($A23-$A$22) -> 0.83309167 | H23: =H$22+(H$28-H$22)/($A$28-$A$22)*($A23-$A$22) -> 0.83531 | I23: =I$22+(I$28-I$22)/($A$28-$A$22)*($A23-$A$22) -> 0.83853667 | ... Z23: =Z$22+(Z$28-Z$22)/($A$28-$A$22)*($A23-$A$22) -> 0.75312
A24: 33 | B24: =B$22+(B$28-B$22)/($A$28-$A$22)*($A24-$A$22) -> 0.8225 | C24: =C$22+(C$28-C$22)/($A$28-$A$22)*($A24-$A$22) -> 0.83025833 | D24: =D$22+(D$28-D$22)/($A$28-$A$22)*($A24-$A$22) -> 0.83148333 | E24: =E$22+(E$28-E$22)/($A$28-$A$22)*($A24-$A$22) -> 0.8316875 | F24: =F$22+(F$28-F$22)/($A$28-$A$22)*($A24-$A$22) -> 0.833525 | G24: =G$22+(G$28-G$22)/($A$28-$A$22)*($A24-$A$22) -> 0.83372917 | H24: =H$22+(H$28-H$22)/($A$28-$A$22)*($A24-$A$22) -> 0.835975 | I24: =I$22+(I$28-I$22)/($A$28-$A$22)*($A24-$A$22) -> 0.83924167 | ... Z24: =Z$22+(Z$28-Z$22)/($A$28-$A$22)*($A24-$A$22) -> 0.7542
A25: 33.2 | B25: =B$22+(B$28-B$22)/($A$28-$A$22)*($A25-$A$22) -> 0.823 | C25: =C$22+(C$28-C$22)/($A$28-$A$22)*($A25-$A$22) -> 0.83085333 | D25: =D$22+(D$28-D$22)/($A$28-$A$22)*($A25-$A$22) -> 0.83209333 | E25: =E$22+(E$28-E$22)/($A$28-$A$22)*($A25-$A$22) -> 0.8323 | F25: =F$22+(F$28-F$22)/($A$28-$A$22)*($A25-$A$22) -> 0.83416 | G25: =G$22+(G$28-G$22)/($A$28-$A$22)*($A25-$A$22) -> 0.83436667 | H25: =H$22+(H$28-H$22)/($A$28-$A$22)*($A25-$A$22) -> 0.83664 | I25: =I$22+(I$28-I$22)/($A$28-$A$22)*($A25-$A$22) -> 0.83994667 | ... Z25: =Z$22+(Z$28-Z$22)/($A$28-$A$22)*($A25-$A$22) -> 0.75528
A26: 33.6 | B26: =B$22+(B$28-B$22)/($A$28-$A$22)*($A26-$A$22) -> 0.824 | C26: =C$22+(C$28-C$22)/($A$28-$A$22)*($A26-$A$22) -> 0.83204333 | D26: =D$22+(D$28-D$22)/($A$28-$A$22)*($A26-$A$22) -> 0.83331333 | E26: =E$22+(E$28-E$22)/($A$28-$A$22)*($A26-$A$22) -> 0.833525 | F26: =F$22+(F$28-F$22)/($A$28-$A$22)*($A26-$A$22) -> 0.83543 | G26: =G$22+(G$28-G$22)/($A$28-$A$22)*($A26-$A$22) -> 0.83564167 | H26: =H$22+(H$28-H$22)/($A$28-$A$22)*($A26-$A$22) -> 0.83797 | I26: =I$22+(I$28-I$22)/($A$28-$A$22)*($A26-$A$22) -> 0.84135667 | ... Z26: =Z$22+(Z$28-Z$22)/($A$28-$A$22)*($A26-$A$22) -> 0.75744 | AB26: =AB$22+(AB$28-AB$22)/($A$28-$A$22)*($A26-$A$22) -> 0.73456
A27: 34.6 | B27: =B$22+(B$28-B$22)/($A$28-$A$22)*($A27-$A$22) -> 0.8265 | C27: =C$22+(C$28-C$22)/($A$28-$A$22)*($A27-$A$22) -> 0.83501833 | D27: =D$22+(D$28-D$22)/($A$28-$A$22)*($A27-$A$22) -> 0.83636333 | E27: =E$22+(E$28-E$22)/($A$28-$A$22)*($A27-$A$22) -> 0.8365875 | F27: =F$22+(F$28-F$22)/($A$28-$A$22)*($A27-$A$22) -> 0.838605 | G27: =G$22+(G$28-G$22)/($A$28-$A$22)*($A27-$A$22) -> 0.83882917 | H27: =H$22+(H$28-H$22)/($A$28-$A$22)*($A27-$A$22) -> 0.841295 | I27: =I$22+(I$28-I$22)/($A$28-$A$22)*($A27-$A$22) -> 0.84488167 | ... Z27: =Z$22+(Z$28-Z$22)/($A$28-$A$22)*($A27-$A$22) -> 0.76284
A28: 40 | B28: =84% -> 0.84 | C28: =$B28+(($O28-$B28)/($O$2-$B$2))*(C$2-$B$2) -> 0.85108333 | D28: =$B28+(($O28-$B28)/($O$2-$B$2))*(D$2-$B$2) -> 0.85283333 | E28: =$B28+(($O28-$B28)/($O$2-$B$2))*(E$2-$B$2) -> 0.853125 | F28: =$B28+(($O28-$B28)/($O$2-$B$2))*(F$2-$B$2) -> 0.85575 | G28: =$B28+(($O28-$B28)/($O$2-$B$2))*(G$2-$B$2) -> 0.85604167 | H28: =$B28+(($O28-$B28)/($O$2-$B$2))*(H$2-$B$2) -> 0.85925 | I28: =$B28+(($O28-$B28)/($O$2-$B$2))*(I$2-$B$2) -> 0.86391667 | J28: =$B28+(($O28-$B28)/($O$2-$B$2))*(J$2-$B$2) -> 0.8645 | ... N28: =$B28+(($O28-$B28)/($O$2-$B$2))*(N$2-$B$2) -> 0.87354167 | O28: =87.5% -> 0.875 | P28: =$O28+(($Z28-$O28)/($Z$2-$O$2))*(P$2-$O$2) -> 0.85978333 | Q28: =$O28+(($Z28-$O28)/($Z$2-$O$2))*(Q$2-$O$2) -> 0.84664167 | R28: =$O28+(($Z28-$O28)/($Z$2-$O$2))*(R$2-$O$2) -> 0.84110833 | S28: =$O28+(($Z28-$O28)/($Z$2-$O$2))*(S$2-$O$2) -> 0.8335 | T28: =$O28+(($Z28-$O28)/($Z$2-$O$2))*(T$2-$O$2) -> 0.83211667 | U28: =$O28+(($Z28-$O28)/($Z$2-$O$2))*(U$2-$O$2) -> 0.823125 | V28: =$O28+(($Z28-$O28)/($Z$2-$O$2))*(V$2-$O$2) -> 0.81413333 | W28: =$O28+(($Z28-$O28)/($Z$2-$O$2))*(W$2-$O$2) -> 0.81275 | ... Y28: =$O28+(($Z28-$O28)/($Z$2-$O$2))*(Y$2-$O$2) -> 0.80306667 | Z28: =79.2% -> 0.792 | AB28: 0.796
A29: 48.9 | B29: =B$28+(B$31-B$28)/($A$31-$A$28)*($A29-$A$28) -> 0.8489 | C29: =C$28+(C$31-C$28)/($A$31-$A$28)*($A29-$A$28) -> 0.86421083 | D29: =D$28+(D$31-D$28)/($A$31-$A$28)*($A29-$A$28) -> 0.86662833 | E29: =E$28+(E$31-E$28)/($A$31-$A$28)*($A29-$A$28) -> 0.86703125 | F29: =F$28+(F$31-F$28)/($A$31-$A$28)*($A29-$A$28) -> 0.8706575 | G29: =G$28+(G$31-G$28)/($A$31-$A$28)*($A29-$A$28) -> 0.87106042 | H29: =H$28+(H$31-H$28)/($A$31-$A$28)*($A29-$A$28) -> 0.8754925 | I29: =I$28+(I$31-I$28)/($A$31-$A$28)*($A29-$A$28) -> 0.88193917 | ... Z29: =Z$28+(Z$31-Z$28)/($A$31-$A$28)*($A29-$A$28) -> 0.82137
A30: 48.9 | B30: =B$28+(B$31-B$28)/($A$31-$A$28)*($A30-$A$28) -> 0.8489 | C30: =C$28+(C$31-C$28)/($A$31-$A$28)*($A30-$A$28) -> 0.86421083 | D30: =D$28+(D$31-D$28)/($A$31-$A$28)*($A30-$A$28) -> 0.86662833 | E30: =E$28+(E$31-E$28)/($A$31-$A$28)*($A30-$A$28) -> 0.86703125 | F30: =F$28+(F$31-F$28)/($A$31-$A$28)*($A30-$A$28) -> 0.8706575 | G30: =G$28+(G$31-G$28)/($A$31-$A$28)*($A30-$A$28) -> 0.87106042 | H30: =H$28+(H$31-H$28)/($A$31-$A$28)*($A30-$A$28) -> 0.8754925 | I30: =I$28+(I$31-I$28)/($A$31-$A$28)*($A30-$A$28) -> 0.88193917 | ... Z30: =Z$28+(Z$31-Z$28)/($A$31-$A$28)*($A30-$A$28) -> 0.82137
A31: 50 | B31: =85% -> 0.85 | C31: =$B31+(($O31-$B31)/($O$2-$B$2))*(C$2-$B$2) -> 0.86583333 | D31: =$B31+(($O31-$B31)/($O$2-$B$2))*(D$2-$B$2) -> 0.86833333 | E31: =$B31+(($O31-$B31)/($O$2-$B$2))*(E$2-$B$2) -> 0.86875 | F31: =$B31+(($O31-$B31)/($O$2-$B$2))*(F$2-$B$2) -> 0.8725 | G31: =$B31+(($O31-$B31)/($O$2-$B$2))*(G$2-$B$2) -> 0.87291667 | H31: =$B31+(($O31-$B31)/($O$2-$B$2))*(H$2-$B$2) -> 0.8775 | I31: =$B31+(($O31-$B31)/($O$2-$B$2))*(I$2-$B$2) -> 0.88416667 | J31: =$B31+(($O31-$B31)/($O$2-$B$2))*(J$2-$B$2) -> 0.885 | ... N31: =$B31+(($O31-$B31)/($O$2-$B$2))*(N$2-$B$2) -> 0.89791667 | O31: =90% -> 0.9 | P31: =$O31+(($Z31-$O31)/($Z$2-$O$2))*(P$2-$O$2) -> 0.88625 | Q31: =$O31+(($Z31-$O31)/($Z$2-$O$2))*(Q$2-$O$2) -> 0.874375 | R31: =$O31+(($Z31-$O31)/($Z$2-$O$2))*(R$2-$O$2) -> 0.869375 | S31: =$O31+(($Z31-$O31)/($Z$2-$O$2))*(S$2-$O$2) -> 0.8625 | T31: =$O31+(($Z31-$O31)/($Z$2-$O$2))*(T$2-$O$2) -> 0.86125 | U31: =$O31+(($Z31-$O31)/($Z$2-$O$2))*(U$2-$O$2) -> 0.853125 | V31: =$O31+(($Z31-$O31)/($Z$2-$O$2))*(V$2-$O$2) -> 0.845 | W31: =$O31+(($Z31-$O31)/($Z$2-$O$2))*(W$2-$O$2) -> 0.84375 | ... Y31: =$O31+(($Z31-$O31)/($Z$2-$O$2))*(Y$2-$O$2) -> 0.835 | Z31: =82.5% -> 0.825
A32: 60 | B32: =85.8% -> 0.858 | C32: =$B32+(($O32-$B32)/($O$2-$B$2))*(C$2-$B$2) -> 0.87351667 | D32: =$B32+(($O32-$B32)/($O$2-$B$2))*(D$2-$B$2) -> 0.87596667 | E32: =$B32+(($O32-$B32)/($O$2-$B$2))*(E$2-$B$2) -> 0.876375 | F32: =$B32+(($O32-$B32)/($O$2-$B$2))*(F$2-$B$2) -> 0.88005 | G32: =$B32+(($O32-$B32)/($O$2-$B$2))*(G$2-$B$2) -> 0.88045833 | H32: =$B32+(($O32-$B32)/($O$2-$B$2))*(H$2-$B$2) -> 0.88495 | I32: =$B32+(($O32-$B32)/($O$2-$B$2))*(I$2-$B$2) -> 0.89148333 | J32: =$B32+(($O32-$B32)/($O$2-$B$2))*(J$2-$B$2) -> 0.8923 | ... N32: =$B32+(($O32-$B32)/($O$2-$B$2))*(N$2-$B$2) -> 0.90495833 | O32: =90.7% -> 0.907 | P32: =$O32+(($Z32-$O32)/($Z$2-$O$2))*(P$2-$O$2) -> 0.89581667 | Q32: =$O32+(($Z32-$O32)/($Z$2-$O$2))*(Q$2-$O$2) -> 0.88615833 | R32: =$O32+(($Z32-$O32)/($Z$2-$O$2))*(R$2-$O$2) -> 0.88209167 | S32: =$O32+(($Z32-$O32)/($Z$2-$O$2))*(S$2-$O$2) -> 0.8765 | T32: =$O32+(($Z32-$O32)/($Z$2-$O$2))*(T$2-$O$2) -> 0.87548333 | U32: =$O32+(($Z32-$O32)/($Z$2-$O$2))*(U$2-$O$2) -> 0.868875 | V32: =$O32+(($Z32-$O32)/($Z$2-$O$2))*(V$2-$O$2) -> 0.86226667 | W32: =$O32+(($Z32-$O32)/($Z$2-$O$2))*(W$2-$O$2) -> 0.86125 | ... Y32: =$O32+(($Z32-$O32)/($Z$2-$O$2))*(Y$2-$O$2) -> 0.85413333 | Z32: =84.6% -> 0.846
A33: 70 | B33: =86% -> 0.86 | C33: =$B33+(($O33-$B33)/($O$2-$B$2))*(C$2-$B$2) -> 0.87583333 | D33: =$B33+(($O33-$B33)/($O$2-$B$2))*(D$2-$B$2) -> 0.87833333 | E33: =$B33+(($O33-$B33)/($O$2-$B$2))*(E$2-$B$2) -> 0.87875 | F33: =$B33+(($O33-$B33)/($O$2-$B$2))*(F$2-$B$2) -> 0.8825 | G33: =$B33+(($O33-$B33)/($O$2-$B$2))*(G$2-$B$2) -> 0.88291667 | H33: =$B33+(($O33-$B33)/($O$2-$B$2))*(H$2-$B$2) -> 0.8875 | I33: =$B33+(($O33-$B33)/($O$2-$B$2))*(I$2-$B$2) -> 0.89416667 | J33: =$B33+(($O33-$B33)/($O$2-$B$2))*(J$2-$B$2) -> 0.895 | ... N33: =$B33+(($O33-$B33)/($O$2-$B$2))*(N$2-$B$2) -> 0.90791667 | O33: =91% -> 0.91 | P33: =$O33+(($Z33-$O33)/($Z$2-$O$2))*(P$2-$O$2) -> 0.9012 | Q33: =$O33+(($Z33-$O33)/($Z$2-$O$2))*(Q$2-$O$2) -> 0.8936 | R33: =$O33+(($Z33-$O33)/($Z$2-$O$2))*(R$2-$O$2) -> 0.8904 | S33: =$O33+(($Z33-$O33)/($Z$2-$O$2))*(S$2-$O$2) -> 0.886 | T33: =$O33+(($Z33-$O33)/($Z$2-$O$2))*(T$2-$O$2) -> 0.8852 | U33: =$O33+(($Z33-$O33)/($Z$2-$O$2))*(U$2-$O$2) -> 0.88 | V33: =$O33+(($Z33-$O33)/($Z$2-$O$2))*(V$2-$O$2) -> 0.8748 | W33: =$O33+(($Z33-$O33)/($Z$2-$O$2))*(W$2-$O$2) -> 0.874 | ... Y33: =$O33+(($Z33-$O33)/($Z$2-$O$2))*(Y$2-$O$2) -> 0.8684 | Z33: =86.2% -> 0.862
A34: 80 | B34: =86.1% -> 0.861 | C34: =$B34+(($O34-$B34)/($O$2-$B$2))*(C$2-$B$2) -> 0.87683333 | D34: =$B34+(($O34-$B34)/($O$2-$B$2))*(D$2-$B$2) -> 0.87933333 | E34: =$B34+(($O34-$B34)/($O$2-$B$2))*(E$2-$B$2) -> 0.87975 | F34: =$B34+(($O34-$B34)/($O$2-$B$2))*(F$2-$B$2) -> 0.8835 | G34: =$B34+(($O34-$B34)/($O$2-$B$2))*(G$2-$B$2) -> 0.88391667 | H34: =$B34+(($O34-$B34)/($O$2-$B$2))*(H$2-$B$2) -> 0.8885 | I34: =$B34+(($O34-$B34)/($O$2-$B$2))*(I$2-$B$2) -> 0.89516667 | J34: =$B34+(($O34-$B34)/($O$2-$B$2))*(J$2-$B$2) -> 0.896 | ... N34: =$B34+(($O34-$B34)/($O$2-$B$2))*(N$2-$B$2) -> 0.90891667 | O34: =91.1% -> 0.911 | P34: =$O34+(($Z34-$O34)/($Z$2-$O$2))*(P$2-$O$2) -> 0.90458333 | Q34: =$O34+(($Z34-$O34)/($Z$2-$O$2))*(Q$2-$O$2) -> 0.89904167 | R34: =$O34+(($Z34-$O34)/($Z$2-$O$2))*(R$2-$O$2) -> 0.89670833 | S34: =$O34+(($Z34-$O34)/($Z$2-$O$2))*(S$2-$O$2) -> 0.8935 | T34: =$O34+(($Z34-$O34)/($Z$2-$O$2))*(T$2-$O$2) -> 0.89291667 | U34: =$O34+(($Z34-$O34)/($Z$2-$O$2))*(U$2-$O$2) -> 0.889125 | V34: =$O34+(($Z34-$O34)/($Z$2-$O$2))*(V$2-$O$2) -> 0.88533333 | W34: =$O34+(($Z34-$O34)/($Z$2-$O$2))*(W$2-$O$2) -> 0.88475 | ... Y34: =$O34+(($Z34-$O34)/($Z$2-$O$2))*(Y$2-$O$2) -> 0.88066667 | Z34: =87.6% -> 0.876
A35: 90 | B35: =86.1% -> 0.861 | C35: =$B35+(($O35-$B35)/($O$2-$B$2))*(C$2-$B$2) -> 0.87683333 | D35: =$B35+(($O35-$B35)/($O$2-$B$2))*(D$2-$B$2) -> 0.87933333 | E35: =$B35+(($O35-$B35)/($O$2-$B$2))*(E$2-$B$2) -> 0.87975 | F35: =$B35+(($O35-$B35)/($O$2-$B$2))*(F$2-$B$2) -> 0.8835 | G35: =$B35+(($O35-$B35)/($O$2-$B$2))*(G$2-$B$2) -> 0.88391667 | H35: =$B35+(($O35-$B35)/($O$2-$B$2))*(H$2-$B$2) -> 0.8885 | I35: =$B35+(($O35-$B35)/($O$2-$B$2))*(I$2-$B$2) -> 0.89516667 | J35: =$B35+(($O35-$B35)/($O$2-$B$2))*(J$2-$B$2) -> 0.896 | ... N35: =$B35+(($O35-$B35)/($O$2-$B$2))*(N$2-$B$2) -> 0.90891667 | O35: =91.1% -> 0.911 | P35: =$O35+(($Z35-$O35)/($Z$2-$O$2))*(P$2-$O$2) -> 0.9066 | Q35: =$O35+(($Z35-$O35)/($Z$2-$O$2))*(Q$2-$O$2) -> 0.9028 | R35: =$O35+(($Z35-$O35)/($Z$2-$O$2))*(R$2-$O$2) -> 0.9012 | S35: =$O35+(($Z35-$O35)/($Z$2-$O$2))*(S$2-$O$2) -> 0.899 | T35: =$O35+(($Z35-$O35)/($Z$2-$O$2))*(T$2-$O$2) -> 0.8986 | U35: =$O35+(($Z35-$O35)/($Z$2-$O$2))*(U$2-$O$2) -> 0.896 | V35: =$O35+(($Z35-$O35)/($Z$2-$O$2))*(V$2-$O$2) -> 0.8934 | W35: =$O35+(($Z35-$O35)/($Z$2-$O$2))*(W$2-$O$2) -> 0.893 | ... Y35: =$O35+(($Z35-$O35)/($Z$2-$O$2))*(Y$2-$O$2) -> 0.8902 | Z35: =88.7% -> 0.887
A36: 100 | B36: =86% -> 0.86 | C36: =$B36+(($O36-$B36)/($O$2-$B$2))*(C$2-$B$2) -> 0.87583333 | D36: =$B36+(($O36-$B36)/($O$2-$B$2))*(D$2-$B$2) -> 0.87833333 | E36: =$B36+(($O36-$B36)/($O$2-$B$2))*(E$2-$B$2) -> 0.87875 | F36: =$B36+(($O36-$B36)/($O$2-$B$2))*(F$2-$B$2) -> 0.8825 | G36: =$B36+(($O36-$B36)/($O$2-$B$2))*(G$2-$B$2) -> 0.88291667 | H36: =$B36+(($O36-$B36)/($O$2-$B$2))*(H$2-$B$2) -> 0.8875 | I36: =$B36+(($O36-$B36)/($O$2-$B$2))*(I$2-$B$2) -> 0.89416667 | J36: =$B36+(($O36-$B36)/($O$2-$B$2))*(J$2-$B$2) -> 0.895 | ... N36: =$B36+(($O36-$B36)/($O$2-$B$2))*(N$2-$B$2) -> 0.90791667 | O36: =91% -> 0.91 | P36: =$O36+(($Z36-$O36)/($Z$2-$O$2))*(P$2-$O$2) -> 0.90761667 | Q36: =$O36+(($Z36-$O36)/($Z$2-$O$2))*(Q$2-$O$2) -> 0.90555833 | R36: =$O36+(($Z36-$O36)/($Z$2-$O$2))*(R$2-$O$2) -> 0.90469167 | S36: =$O36+(($Z36-$O36)/($Z$2-$O$2))*(S$2-$O$2) -> 0.9035 | T36: =$O36+(($Z36-$O36)/($Z$2-$O$2))*(T$2-$O$2) -> 0.90328333 | U36: =$O36+(($Z36-$O36)/($Z$2-$O$2))*(U$2-$O$2) -> 0.901875 | V36: =$O36+(($Z36-$O36)/($Z$2-$O$2))*(V$2-$O$2) -> 0.90046667 | W36: =$O36+(($Z36-$O36)/($Z$2-$O$2))*(W$2-$O$2) -> 0.90025 | ... Y36: =$O36+(($Z36-$O36)/($Z$2-$O$2))*(Y$2-$O$2) -> 0.89873333 | Z36: =89.7% -> 0.897

Sheet engine data
B1: ENGINE DATA
B3: raw data | K3: v,m*(71rpm/v)*(16/15)
B4: [per 2mm] | C4: [A/B/C] | D4: [g] | E4: [g] | F4: [s] | G4: [V] | H4: [A] | I4: [g/s] | J4: [kW] | K4: [rpm] | L4: [%] | M4: [kW] | N4: [Nm] | O4: [g/kWh]
A5: # | B5: throttle | C5: load | D5: Fuel Before | E5: Fuel After | F5: Time Elapsed | G5: Voltage-M | H5: Current-M | I5: Fuel Consumption | J5: Power-M | K5: rpm-E | L5: Efficiency-M | M5: Power-E | N5: Torque-E | O5: ave SFC
A6: 1 | B6: 1 | C6: A | D6: 2497 | E6: 2490 | F6: 120 | G6: 16.5 | H6: 8.8 | I6: =(D6-E6)/F6 -> 0.058333333 | J6: =G6*H6/1000 -> 0.1452 | K6: =G6*71*(16/15) -> 1249.6 | L6: 0.4169 | M6: =J6/L6 -> 0.34828496 | N6: =(M6*1000)/(K6*2*PI()/60) -> 2.6615528 | O6: =I6*3600/M6 -> 602.95455
A7: 2 | B7: 2 | C7: A | D7: 2487 | E7: 2476 | F7: 120 | G7: 23.5 | H7: 20.5 | I7: =(D7-E7)/F7 -> 0.091666667 | J7: =G7*H7/1000 -> 0.48175 | K7: =G7*71*(16/15) -> 1779.7333 | L7: 0.74807292 | M7: =J7/L7 -> 0.64398802 | N7: =(M7*1000)/(K7*2*PI()/60) -> 3.4553675 | O7: =I7*3600/M7 -> 512.43189
A8: 3 | B8: 3 | C8: A | D8: 2413 | E8: 2397 | F8: 120 | G8: 30.2 | H8: 25.4 | I8: =(D8-E8)/F8 -> 0.13333333 | J8: =G8*H8/1000 -> 0.76708 | K8: =G8*71*(16/15) -> 2287.1467 | L8: 0.74277033 | M8: =J8/L8 -> 1.0327284 | N8: =(M8*1000)/(K8*2*PI()/60) -> 4.3118483 | O8: =I8*3600/M8 -> 464.78824
A9: 4* | B9: 4 | C9: A | D9: 2885 | E9: 2864 | F9: 120 | G9: 33 | H9: 26 | I9: =(D9-E9)/F9 -> 0.175 | J9: =G9*H9/1000 -> 0.858 | K9: =G9*71*(16/15) -> 2499.2 | L9: 0.72535 | M9: =J9/L9 -> 1.1828772 | N9: =(M9*1000)/(K9*2*PI()/60) -> 4.5197045 | O9: =I9*3600/M9 -> 532.59965
A10: 5 | B10: 4 | C10: AB | D10: 2857 | E10: 2820 | F10: 120 | G10: 31.5 | H10: 48.9 | I10: =(D10-E10)/F10 -> 0.30833333 | J10: =G10*H10/1000 -> 1.54035 | K10: =G10*71*(16/15) -> 2385.6 | L10: 0.849825 | M10: =J10/L10 -> 1.8125496 | N10: =(M10*1000)/(K10*2*PI()/60) -> 7.2554385 | O10: =I10*3600/M10 -> 612.39702
A11: 6 | B11: 3 | C11: AB | D11: 2809 | E11: 2784 | F11: 120 | G11: 26.2 | H11: 48.9 | I11: =(D11-E11)/F11 -> 0.20833333 | J11: =G11*H11/1000 -> 1.28118 | K11: =G11*71*(16/15) -> 1984.2133 | L11: 0.88333867 | M11: =J11/L11 -> 1.4503837 | N11: =(M11*1000)/(K11*2*PI()/60) -> 6.9801688 | O11: =I11*3600/M11 -> 517.10454
A12: 7 | B12: 2 | C12: AB | D12: 2782 | E12: 2770 | F12: 120 | G12: 20.2 | H12: 28.6 | I12: =(D12-E12)/F12 -> 0.1 | J12: =G12*H12/1000 -> 0.57772 | K12: =G12*71*(16/15) -> 1529.8133 | L12: 0.81540167 | M12: =J12/L12 -> 0.70850971 | N12: =(M12*1000)/(K12*2*PI()/60) -> 4.4226111 | O12: =I12*3600/M12 -> 508.10877
A13: 8 | B13: 1 | C13: AB | D13: 2765 | E13: 2754 | F13: 120 | G13: 18.6 | H13: 22.7 | I13: =(D13-E13)/F13 -> 0.091666667 | J13: =G13*H13/1000 -> 0.42222 | K13: =G13*71*(16/15) -> 1408.64 | L13: 0.7553725 | M13: =J13/L13 -> 0.55895601 | N13: =(M13*1000)/(K13*2*PI()/60) -> 3.7892128 | O13: =I13*3600/M13 -> 590.38635
A14: 9 | B14: 1 | C14: C | D14: 2750 | E14: 2742 | F14: 180 | G14: 17.4 | H14: 0.38 | I14: =(D14-E14)/F14 -> 0.044444444 | J14: =G14*H14/1000 -> 0.006612 | K14: =G14*71*(16/15) -> 1317.76 | L14: 0.018031 | M14: =J14/L14 -> 0.36670179 | N14: 2.6573459 | O14: =I14*3600/M14 -> 436.32184
A15: 10 | B15: 2 | C15: C | D15: 2718 | E15: 2708 | F15: =120+45 -> 165 | G15: 23 | H15: 0.58 | I15: =(D15-E15)/F15 -> 0.060606061 | J15: =G15*H15/1000 -> 0.01334 | K15: =G15*71*(16/15) -> 1741.8667 | L15: 0.027791667 | M15: =J15/L15 -> 0.48 | N15: =(M15*1000)/(K15*2*PI()/60) -> 2.6314657 | O15: =I15*3600/M15 -> 454.54545
A16: 11 | B16: 3 | C16: C | D16: 2696 | E16: 2686 | F16: =60+50 -> 110 | G16: 30 | H16: 8.6 | I16: =(D16-E16)/F16 -> 0.090909091 | J16: =G16*H16/1000 -> 0.258 | K16: =G16*71*(16/15) -> 2272 | L16: 0.36765 | M16: =J16/L16 -> 0.70175439 | N16: =(M16*1000)/(K16*2*PI()/60) -> 2.9494986 | O16: =I16*3600/M16 -> 466.36364
A17: 12 | B17: 4 | C17: C | D17: 2681 | E17: 2671 | F17: =60+23 -> 83 | G17: 34.4 | H17: 11 | I17: =(D17-E17)/F17 -> 0.12048193 | J17: =G17*H17/1000 -> 0.3784 | K17: =G17*71*(16/15) -> 2605.2267 | L17: 0.41593333 | M17: =J17/L17 -> 0.90976118 | N17: =(M17*1000)/(K17*2*PI()/60) -> 3.3346731 | O17: =I17*3600/M17 -> 476.75692
A18: 13 | B18: 4 | C18: AC | D18: 2662 | E18: 2652 | F18: 51 | G18: 32.8 | H18: 34.6 | I18: =(D18-E18)/F18 -> 0.19607843 | J18: =G18*H18/1000 -> 1.13488 | K18: =G18*71*(16/15) -> 2484.0533 | L18: 0.78698933 | M18: =J18/L18 -> 1.4420526 | N18: =(M18*1000)/(K18*2*PI()/60) -> 5.5435959 | O18: =I18*3600/M18 -> 489.49835
A19: 14 | B19: 3 | C19: AC | D19: 2645 | E19: 2635 | F19: =60+9 -> 69 | G19: 28.1 | H19: 33 | I19: =(D19-E19)/F19 -> 0.14492754 | J19: =G19*H19/1000 -> 0.9273 | K19: =G19*71*(16/15) -> 2128.1067 | L19: 0.81529333 | M19: =J19/L19 -> 1.137382 | N19: =(M19*1000)/(K19*2*PI()/60) -> 5.1036908 | O19: =I19*3600/M19 -> 458.71933
A20: 15 | B20: 2 | C20: AC | D20: 2635 | E20: 2625 | F20: =60+45 -> 105 | G20: 20.7 | H20: 20.9 | I20: =(D20-E20)/F20 -> 0.095238095 | J20: =G20*H20/1000 -> 0.43263 | K20: =G20*71*(16/15) -> 1567.68 | L20: 0.74384625 | M20: =J20/L20 -> 0.58161213 | N20: =(M20*1000)/(K20*2*PI()/60) -> 3.5428064 | O20: =I20*3600/M20 -> 589.49449
A21: 16 | B21: 1 | C21: AC | D21: 2627 | E21: 2617 | F21: =120+39 -> 159 | G21: 16.4 | H21: 12.7 | I21: =(D21-E21)/F21 -> 0.062893082 | J21: =G21*H21/1000 -> 0.20828 | K21: =G21*71*(16/15) -> 1242.0267 | L21: 0.54094167 | M21: =J21/L21 -> 0.38503227 | N21: =(M21*1000)/(K21*2*PI()/60) -> 2.9603128 | O21: =I21*3600/M21 -> 588.04186
A22: 17 | B22: 1 | C22: BC | D22: 2606 | E22: =2596 -> 2596 | F22: =120+45 -> 165 | G22: 15.8 | H22: 11.8 | I22: =(D22-E22)/F22 -> 0.060606061 | J22: =G22*H22/1000 -> 0.18644 | K22: =G22*71*(16/15) -> 1196.5867 | L22: 0.51779167 | M22: =J22/L22 -> 0.36006759 | N22: =(M22*1000)/(K22*2*PI()/60) -> 2.8735004 | O22: =I22*3600/M22 -> 605.94683
A23: 18 | B23: 2 | C23: BC | D23: 2574 | E23: =2564 -> 2564 | F23: =60+57 -> 117 | G23: 20.9 | H23: 21.1 | I23: =(D23-E23)/F23 -> 0.085470085 | J23: =G23*H23/1000 -> 0.44099 | K23: =G23*71*(16/15) -> 1582.8267 | L23: 0.74628458 | M23: =J23/L23 -> 0.59091399 | N23: =(M23*1000)/(K23*2*PI()/60) -> 3.5650227 | O23: =I23*3600/M23 -> 520.70574
A24: 19 | B24: 3 | C24: BC | D24: 2547 | E24: 2537 | F24: 67 | G24: 28.9 | H24: 32.8 | I24: =(D24-E24)/F24 -> 0.14925373 | J24: =G24*H24/1000 -> 0.94792 | K24: =G24*71*(16/15) -> 2188.6933 | L24: 0.80819233 | M24: =J24/L24 -> 1.1728891 | N24: =(M24*1000)/(K24*2*PI()/60) -> 5.11733 | O24: =I24*3600/M24 -> 458.11102
A25: 20 | B25: 4 | C25: BC | D25: 2530 | E25: =2520 -> 2520 | F25: 54.3 | G25: 33.7 | H25: 33.2 | I25: =(D25-E25)/F25 -> 0.18416206 | J25: =G25*H25/1000 -> 1.11884 | K25: =G25*71*(16/15) -> 2552.2133 | L25: 0.773013 | M25: =J25/L25 -> 1.4473754 | N25: =(M25*1000)/(K25*2*PI()/60) -> 5.415463 | O25: =I25*3600/M25 -> 458.05907
A26: 21 | B26: 5 | C26: BC | D26: 2510 | E26: =2500 -> 2500 | F26: 48.54 | G26: 37.1 | H26: 33.6 | I26: =(D26-E26)/F26 -> 0.20601566 | J26: =G26*H26/1000 -> 1.24656 | K26: =G26*71*(16/15) -> 2809.7067 | L26: 0.73456 | M26: =J26/L26 -> 1.6970159 | N26: =(M26*1000)/(K26*2*PI()/60) -> 5.7676157 | O26: =I26*3600/M26 -> 437.0356
A27: 22 | B27: 1 | C27: B | D27: 2439 | E27: =2429 -> 2429 | F27: =180+11 -> 191 | G27: 17.5 | H27: 9.6 | I27: =(D27-E27)/F27 -> 0.052356021 | J27: =G27*H27/1000 -> 0.168 | K27: =G27*71*(16/15) -> 1325.3333 | L27: 0.4556 | M27: =J27/L27 -> 0.36874451 | N27: =(M27*1000)/(K27*2*PI()/60) -> 2.6568793 | O27: =I27*3600/M27 -> 511.14435
A28: 23* | B28: 2 | C28: B | D28: 2418 | E28: =2408 -> 2408 | F28: =120+55 -> 175 | G28: 20.4 | H28: 12.9 | I28: =(D28-E28)/F28 -> 0.057142857 | J28: =G28*H28/1000 -> 0.26316 | K28: =G28*71*(16/15) -> 1544.96 | L28: 0.551675 | M28: =J28/L28 -> 0.47701998 | N28: =(M28*1000)/(K28*2*PI()/60) -> 2.9484293 | O28: =I28*3600/M28 -> 431.24878
L31: rpm : N = x
L32: torque: Tb = y
L33: BSFC = z

Sheet goering_matlab
B1: GOERING
B3: z = (3600/Hg)*(1+De/(4*pi*y)*(A0+A1*(x/1000)+A2*(x/1000)^2))*((1/e_ito)*(1+y^nexp*(B0+B1*(x/1000)^(-1)+B2*(x/1000)^(-2)+B3*(x/1000)^(-3)+B4*(x/10000)^(-4))))
B4: actual data
B5: N (x) | C5: T_b (y) | D5: BSFC (z) | H5: y = (3600/44000)*(1+211/(4*pi*x2)*(a0+a1*(x1/1000)+a2*(x1/1000)^2))*((1/a3)*(1+x2^a4*(a5+a6*(x1/1000)^(-1)+a7*(x1/1000)^(-2)+a8*(x1/1000)^(-3)+a9*(x1/10000)^(-4))))
A6: # | B6: [rpm] | C6: [Nm] | D6: [g/kWh]
A7: 1 | B7: ='engine data'!K6 -> 1249.6 | C7: ='engine data'!N6 -> 2.6615528 | D7: ='engine data'!O6 -> 602.95455 | H7: Y = (3600/44000) · (1+211/(4 · pi · x2) · (a0+a1 · (x1/1000)+a2 · (x1/1000)^2)) · ((1/a3) · (1+x2^a4 · (a5+a6 · (x1/1000)^(-1)+a7 · (x1/1000)^(-2)+a8 · (x1/1000)^(-3)+a9 · (x1/10000)^(-4))))
A8: 2 | B8: ='engine data'!K7 -> 1779.7333 | C8: ='engine data'!N7 -> 3.4553675 | D8: ='engine data'!O7 -> 512.43189
A9: 3 | B9: ='engine data'!K8 -> 2287.1467 | C9: ='engine data'!N8 -> 4.3118483 | D9: ='engine data'!O8 -> 464.78824 | H9: z = (3600/Hg)
A10: 4* | B10: ='engine data'!K9 -> 2499.2 | C10: ='engine data'!N9 -> 4.5197045 | D10: ='engine data'!O9 -> 532.59965 | I10: *(1+De/(4*pi*y)*(A0+A1*(x/1000)+A2*(x/1000)^2))
A11: 5 | B11: ='engine data'!K10 -> 2385.6 | C11: ='engine data'!N10 -> 7.2554385 | D11: ='engine data'!O10 -> 612.39702 | I11: *((1/e_ito)*(1+y^nexp*(B0+B1*(x/1000)^(-1)+B2*(x/1000)^(-2)+B3*(x/1000)^(-3)+B4*(x/10000)^(-4))))
A12: 6 | B12: ='engine data'!K11 -> 1984.2133 | C12: ='engine data'!N11 -> 6.9801688 | D12: ='engine data'!O11 -> 517.10454
A13: 7 | B13: ='engine data'!K12 -> 1529.8133 | C13: ='engine data'!N12 -> 4.4226111 | D13: ='engine data'!O12 -> 508.10877
A14: 8 | B14: ='engine data'!K13 -> 1408.64 | C14: ='engine data'!N13 -> 3.7892128 | D14: ='engine data'!O13 -> 590.38635
A15: 9 | B15: ='engine data'!K14 -> 1317.76 | C15: ='engine data'!N14 -> 2.6573459 | D15: ='engine data'!O14 -> 436.32184 | H15: 3600/Hg | I15: =3600/44000 -> 0.081818182
A16: 10 | B16: ='engine data'!K15 -> 1741.8667 | C16: ='engine data'!N15 -> 2.6314657 | D16: ='engine data'!O15 -> 454.54545 | H16: De/4*pi | I16: =211/(4*PI()) -> 16.790846
A17: 11 | B17: ='engine data'!K16 -> 2272 | C17: ='engine data'!N16 -> 2.9494986 | D17: ='engine data'!O16 -> 466.36364
A18: 12 | B18: ='engine data'!K17 -> 2605.2267 | C18: ='engine data'!N17 -> 3.3346731 | D18: ='engine data'!O17 -> 476.75692 | H18: Y = (3600/44000) · (1+211/(4 · pi) · x2^-1 · (a0+a1 · (x1/1000)+a2 · (x1/1000)^2)) · ((1/a3) · (1+x2^a4 · (a5+a6 · (x1/1000)^(-1)+a7 · (x1/1000)^(-2)+a8 · (x1/1000)^(-3)+a9 · (x1/10000)^(-4))))
A19: 13 | B19: ='engine data'!K18 -> 2484.0533 | C19: ='engine data'!N18 -> 5.5435959 | D19: ='engine data'!O18 -> 489.49835
A20: 14 | B20: ='engine data'!K19 -> 2128.1067 | C20: ='engine data'!N19 -> 5.1036908 | D20: ='engine data'!O19 -> 458.71933
A21: 15 | B21: ='engine data'!K20 -> 1567.68 | C21: ='engine data'!N20 -> 3.5428064 | D21: ='engine data'!O20 -> 589.49449
A22: 16 | B22: ='engine data'!K21 -> 1242.0267 | C22: ='engine data'!N21 -> 2.9603128 | D22: ='engine data'!O21 -> 588.04186
A23: 17 | B23: ='engine data'!K22 -> 1196.5867 | C23: ='engine data'!N22 -> 2.8735004 | D23: ='engine data'!O22 -> 605.94683
A24: 18 | B24: ='engine data'!K23 -> 1582.8267 | C24: ='engine data'!N23 -> 3.5650227 | D24: ='engine data'!O23 -> 520.70574
A25: 19 | B25: ='engine data'!K24 -> 2188.6933 | C25: ='engine data'!N24 -> 5.11733 | D25: ='engine data'!O24 -> 458.11102
A26: 20 | B26: ='engine data'!K25 -> 2552.2133 | C26: ='engine data'!N25 -> 5.415463 | D26: ='engine data'!O25 -> 458.05907
A27: 21 | B27: ='engine data'!K26 -> 2809.7067 | C27: ='engine data'!N26 -> 5.7676157 | D27: ='engine data'!O26 -> 437.0356
A28: 22 | B28: ='engine data'!K27 -> 1325.3333 | C28: ='engine data'!N27 -> 2.6568793 | D28: ='engine data'!O27 -> 511.14435
A29: 23* | B29: ='engine data'!K28 -> 1544.96 | C29: ='engine data'!N28 -> 2.9484293 | D29: ='engine data'!O28 -> 431.24878
B31: arrays
B32: rpm | C32: 1249.6 1779.73333333333 2287.14666666667 2499.2 2385.6 1984.21333333333 1529.81333333333 1408.64 1317.76 1741.86666666667 2272 2605.22666666667 2484.05333333333 2128.10666666667 1567.68 1242.02666666667 1196.58666666667 1582.82666666667 2188.69333333333 2552.21333333333 2809.70666666667 1325.33333333333 1544.96
B33: tb | C33: 2.66155280357326 3.45536745928218 4.3118483380818 4.51970450927327 7.25543851144406 6.98016883632546 4.42261106372708 3.78921281139137 2.65734592348331 2.63146568492417 2.94949857472008 3.33467311611344 5.54359586847073 5.10369083636934 3.54280637839879 2.96031275155343 2.87350038983029 3.56502266196961 5.11733003506074 5.41546303503331 5.7676156511761 2.65687931313679 2.94842928625324
B34: bsfc | C34: 6.02954545454548 5.12431888946546 4.64788235907598 5.32599650349653 6.12397020157758 5.17104544248271 5.08108772415707 5.90386350717632 4.36321839080451 4.54545454545461 4.66363636363643 4.76756921979663 4.89498345510494 4.5871933007937 5.89494487206166 5.88041859470729 6.05946831542206 5.20705743080407 4.58111018878103 4.58059067096137 4.37035602075806 5.11144353029177 4.31248778581206
B36: constraints
B37: a0 | C37: 0 | D37: inf | E37: +
B38: a1 | C38: inf | D38: 0 | E38: -
B39: a2 | C39: 0 | D39: inf | E39: +
B40: b0 | C40: inf | D40: inf
B41: b1 | C41: inf | D41: inf
B42: b2 | C42: inf | D42: inf
B43: b3 | C43: inf | D43: inf
...

Sheet goering_excel
C1: S | D1: Tb
B2: # | C2: Speed (rpm) | D2: Torque (Nm) | E2: Ave. SFC (g. kWh) | F2: BSFC model | G2: error | H2: mse | I2: %err | K2: pearson
B3: 1 | C3: 1249.6 | D3: 2.6615528 | E3: 6.0295455 | F3: =(3600/$D$29) * (1 + ($C$29/(4*PI()*D3)) * ($B$34 + $C$34*(C3/1000) + $D$34*(C3/1000)^2)) * (1/$E$34 * (1 + D3^$F$34 * ($G$34 + $H$34/(C3/1000) + $I$34/((C3/1000)^2) + $J$34/((C3/1000)^3) + $K$34/((C3/1000)^4)))) -> 5.6655762 | G3: =E3-F3 -> 0.36396926 | H3: =G3^2 -> 0.13247362 | I3: =G3/E3 -> 0.060364294 | K3: =PEARSON(E3:E25,F3:F25) -> 0.63728301
B4: 2 | C4: 1779.7333 | D4: 3.4553675 | E4: 5.1243189 | F4: =(3600/$D$29) * (1 + ($C$29/(4*PI()*D4)) * ($B$34 + $C$34*(C4/1000) + $D$34*(C4/1000)^2)) * (1/$E$34 * (1 + D4^$F$34 * ($G$34 + $H$34/(C4/1000) + $I$34/((C4/1000)^2) + $J$34/((C4/1000)^3) + $K$34/((C4/1000)^4)))) -> 4.6718559 | G4: =E4-F4 -> 0.45246302 | H4: =G4^2 -> 0.20472278 | I4: =G4/E4 -> 0.088297201
B5: 3 | C5: 2287.1467 | D5: 4.3118483 | E5: 4.6478824 | F5: =(3600/$D$29) * (1 + ($C$29/(4*PI()*D5)) * ($B$34 + $C$34*(C5/1000) + $D$34*(C5/1000)^2)) * (1/$E$34 * (1 + D5^$F$34 * ($G$34 + $H$34/(C5/1000) + $I$34/((C5/1000)^2) + $J$34/((C5/1000)^3) + $K$34/((C5/1000)^4)))) -> 4.6728165 | G5: =E5-F5 -> -0.024934184 | H5: =G5^2 -> 0.00062171352 | I5: =G5/E5 -> -0.0053646332
B6: 4* | C6: 2499.2 | D6: 4.5197045 | E6: 5.3259965 | F6: =(3600/$D$29) * (1 + ($C$29/(4*PI()*D6)) * ($B$34 + $C$34*(C6/1000) + $D$34*(C6/1000)^2)) * (1/$E$34 * (1 + D6^$F$34 * ($G$34 + $H$34/(C6/1000) + $I$34/((C6/1000)^2) + $J$34/((C6/1000)^3) + $K$34/((C6/1000)^4)))) -> 4.7585211 | G6: =E6-F6 -> 0.56747544 | H6: =G6^2 -> 0.32202838 | I6: =G6/E6 -> 0.10654822
B7: 5 | C7: 2385.6 | D7: 7.2554385 | E7: 6.1239702 | F7: =(3600/$D$29) * (1 + ($C$29/(4*PI()*D7)) * ($B$34 + $C$34*(C7/1000) + $D$34*(C7/1000)^2)) * (1/$E$34 * (1 + D7^$F$34 * ($G$34 + $H$34/(C7/1000) + $I$34/((C7/1000)^2) + $J$34/((C7/1000)^3) + $K$34/((C7/1000)^4)))) -> 5.349802 | G7: =E7-F7 -> 0.77416819 | H7: =G7^2 -> 0.59933639 | I7: =G7/E7 -> 0.12641606
B8: 6 | C8: 1984.2133 | D8: 6.9801688 | E8: 5.1710454 | F8: =(3600/$D$29) * (1 + ($C$29/(4*PI()*D8)) * ($B$34 + $C$34*(C8/1000) + $D$34*(C8/1000)^2)) * (1/$E$34 * (1 + D8^$F$34 * ($G$34 + $H$34/(C8/1000) + $I$34/((C8/1000)^2) + $J$34/((C8/1000)^3) + $K$34/((C8/1000)^4)))) -> 5.4265141 | G8: =E8-F8 -> -0.25546867 | H8: =G8^2 -> 0.065264242 | I8: =G8/E8 -> -0.049403679
B9: 7 | C9: 1529.8133 | D9: 4.4226111 | E9: 5.0810877 | F9: =(3600/$D$29) * (1 + ($C$29/(4*PI()*D9)) * ($B$34 + $C$34*(C9/1000) + $D$34*(C9/1000)^2)) * (1/$E$34 * (1 + D9^$F$34 * ($G$34 + $H$34/(C9/1000) + $I$34/((C9/1000)^2) + $J$34/((C9/1000)^3) + $K$34/((C9/1000)^4)))) -> 5.3513421 | G9: =E9-F9 -> -0.27025435 | H9: =G9^2 -> 0.073037414 | I9: =G9/E9 -> -0.053188287
B10: 8 | C10: 1408.64 | D10: 3.7892128 | E10: 5.9038635 | F10: =(3600/$D$29) * (1 + ($C$29/(4*PI()*D10)) * ($B$34 + $C$34*(C10/1000) + $D$34*(C10/1000)^2)) * (1/$E$34 * (1 + D10^$F$34 * ($G$34 + $H$34/(C10/1000) + $I$34/((C10/1000)^2) + $J$34/((C10/1000)^3) + $K$34/((C10/1000)^4)))) -> 5.4735791 | G10: =E10-F10 -> 0.43028445 | H10: =G10^2 -> 0.18514471 | I10: =G10/E10 -> 0.072881842
B11: 9 | C11: 1317.76 | D11: 2.6573459 | E11: 4.3632184 | F11: =(3600/$D$29) * (1 + ($C$29/(4*PI()*D11)) * ($B$34 + $C$34*(C11/1000) + $D$34*(C11/1000)^2)) * (1/$E$34 * (1 + D11^$F$34 * ($G$34 + $H$34/(C11/1000) + $I$34/((C11/1000)^2) + $J$34/((C11/1000)^3) + $K$34/((C11/1000)^4)))) -> 5.3855076 | G11: =E11-F11 -> -1.0222892 | H11: =G11^2 -> 1.0450751 | I11: =G11/E11 -> -0.23429704
B12: 10 | C12: 1741.8667 | D12: 2.6314657 | E12: 4.5454545 | F12: =(3600/$D$29) * (1 + ($C$29/(4*PI()*D12)) * ($B$34 + $C$34*(C12/1000) + $D$34*(C12/1000)^2)) * (1/$E$34 * (1 + D12^$F$34 * ($G$34 + $H$34/(C12/1000) + $I$34/((C12/1000)^2) + $J$34/((C12/1000)^3) + $K$34/((C12/1000)^4)))) -> 4.5344318 | G12: =E12-F12 -> 0.011022737 | H12: =G12^2 -> 0.00012150074 | I12: =G12/E12 -> 0.0024250022
B13: 11 | C13: 2272 | D13: 2.9494986 | E13: 4.6636364 | F13: =(3600/$D$29) * (1 + ($C$29/(4*PI()*D13)) * ($B$34 + $C$34*(C13/1000) + $D$34*(C13/1000)^2)) * (1/$E$34 * (1 + D13^$F$34 * ($G$34 + $H$34/(C13/1000) + $I$34/((C13/1000)^2) + $J$34/((C13/1000)^3) + $K$34/((C13/1000)^4)))) -> 4.4405339 | G13: =E13-F13 -> 0.22310243 | H13: =G13^2 -> 0.049774695 | I13: =G13/E13 -> 0.047838728
B14: 12 | C14: 2605.2267 | D14: 3.3346731 | E14: 4.7675692 | F14: =(3600/$D$29) * (1 + ($C$29/(4*PI()*D14)) * ($B$34 + $C$34*(C14/1000) + $D$34*(C14/1000)^2)) * (1/$E$34 * (1 + D14^$F$34 * ($G$34 + $H$34/(C14/1000) + $I$34/((C14/1000)^2) + $J$34/((C14/1000)^3) + $K$34/((C14/1000)^4)))) -> 4.6115146 | G14: =E14-F14 -> 0.15605462 | H14: =G14^2 -> 0.024353045 | I14: =G14/E14 -> 0.032732534 | K14: 211
B15: 13 | C15: 2484.0533 | D15: 5.5435959 | E15: 4.8949835 | F15: =(3600/$D$29) * (1 + ($C$29/(4*PI()*D15)) * ($B$34 + $C$34*(C15/1000) + $D$34*(C15/1000)^2)) * (1/$E$34 * (1 + D15^$F$34 * ($G$34 + $H$34/(C15/1000) + $I$34/((C15/1000)^2) + $J$34/((C15/1000)^3) + $K$34/((C15/1000)^4)))) -> 4.9672686 | G15: =E15-F15 -> -0.072285171 | H15: =G15^2 -> 0.0052251459 | I15: =G15/E15 -> -0.014767194
B16: 14 | C16: 2128.1067 | D16: 5.1036908 | E16: 4.5871933 | F16: =(3600/$D$29) * (1 + ($C$29/(4*PI()*D16)) * ($B$34 + $C$34*(C16/1000) + $D$34*(C16/1000)^2)) * (1/$E$34 * (1 + D16^$F$34 * ($G$34 + $H$34/(C16/1000) + $I$34/((C16/1000)^2) + $J$34/((C16/1000)^3) + $K$34/((C16/1000)^4)))) -> 4.8646297 | G16: =E16-F16 -> -0.27743635 | H16: =G16^2 -> 0.076970928 | I16: =G16/E16 -> -0.060480632 | K16: =1/0.85 -> 1.1764706
B17: 15 | C17: 1567.68 | D17: 3.5428064 | E17: 5.8949449 | F17: =(3600/$D$29) * (1 + ($C$29/(4*PI()*D17)) * ($B$34 + $C$34*(C17/1000) + $D$34*(C17/1000)^2)) * (1/$E$34 * (1 + D17^$F$34 * ($G$34 + $H$34/(C17/1000) + $I$34/((C17/1000)^2) + $J$34/((C17/1000)^3) + $K$34/((C17/1000)^4)))) -> 4.9911764 | G17: =E17-F17 -> 0.90376845 | H17: =G17^2 -> 0.81679741 | I17: =G17/E17 -> 0.15331245
B18: 16 | C18: 1242.0267 | D18: 2.9603128 | E18: 5.8804186 | F18: =(3600/$D$29) * (1 + ($C$29/(4*PI()*D18)) * ($B$34 + $C$34*(C18/1000) + $D$34*(C18/1000)^2)) * (1/$E$34 * (1 + D18^$F$34 * ($G$34 + $H$34/(C18/1000) + $I$34/((C18/1000)^2) + $J$34/((C18/1000)^3) + $K$34/((C18/1000)^4)))) -> 5.8201292 | G18: =E18-F18 -> 0.06028937 | H18: =G18^2 -> 0.0036348082 | I18: =G18/E18 -> 0.010252564
B19: 17 | C19: 1196.5867 | D19: 2.8735004 | E19: 6.0594683 | F19: =(3600/$D$29) * (1 + ($C$29/(4*PI()*D19)) * ($B$34 + $C$34*(C19/1000) + $D$34*(C19/1000)^2)) * (1/$E$34 * (1 + D19^$F$34 * ($G$34 + $H$34/(C19/1000) + $I$34/((C19/1000)^2) + $J$34/((C19/1000)^3) + $K$34/((C19/1000)^4)))) -> 6.0214101 | G19: =E19-F19 -> 0.038058202 | H19: =G19^2 -> 0.0014484267 | I19: =G19/E19 -> 0.0062807824
B20: 18 | C20: 1582.8267 | D20: 3.5650227 | E20: 5.2070574 | F20: =(3600/$D$29) * (1 + ($C$29/(4*PI()*D20)) * ($B$34 + $C$34*(C20/1000) + $D$34*(C20/1000)^2)) * (1/$E$34 * (1 + D20^$F$34 * ($G$34 + $H$34/(C20/1000) + $I$34/((C20/1000)^2) + $J$34/((C20/1000)^3) + $K$34/((C20/1000)^4)))) -> 4.9690509 | G20: =E20-F20 -> 0.23800649 | H20: =G20^2 -> 0.056647089 | I20: =G20/E20 -> 0.045708443
B21: 19 | C21: 2188.6933 | D21: 5.11733 | E21: 4.5811102 | F21: =(3600/$D$29) * (1 + ($C$29/(4*PI()*D21)) * ($B$34 + $C$34*(C21/1000) + $D$34*(C21/1000)^2)) * (1/$E$34 * (1 + D21^$F$34 * ($G$34 + $H$34/(C21/1000) + $I$34/((C21/1000)^2) + $J$34/((C21/1000)^3) + $K$34/((C21/1000)^4)))) -> 4.8546208 | G21: =E21-F21 -> -0.27351064 | H21: =G21^2 -> 0.074808071 | I21: =G21/E21 -> -0.059704008
B22: 20 | C22: 2552.2133 | D22: 5.415463 | E22: 4.5805907 | F22: =(3600/$D$29) * (1 + ($C$29/(4*PI()*D22)) * ($B$34 + $C$34*(C22/1000) + $D$34*(C22/1000)^2)) * (1/$E$34 * (1 + D22^$F$34 * ($G$34 + $H$34/(C22/1000) + $I$34/((C22/1000)^2) + $J$34/((C22/1000)^3) + $K$34/((C22/1000)^4)))) -> 4.9596034 | G22: =E22-F22 -> -0.37901275 | H22: =G22^2 -> 0.14365067 | I22: =G22/E22 -> -0.082743205
B23: 21 | C23: 2809.7067 | D23: 5.7676157 | E23: 4.370356 | F23: =(3600/$D$29) * (1 + ($C$29/(4*PI()*D23)) * ($B$34 + $C$34*(C23/1000) + $D$34*(C23/1000)^2)) * (1/$E$34 * (1 + D23^$F$34 * ($G$34 + $H$34/(C23/1000) + $I$34/((C23/1000)^2) + $J$34/((C23/1000)^3) + $K$34/((C23/1000)^4)))) -> 5.1522631 | G23: =E23-F23 -> -0.78190708 | H23: =G23^2 -> 0.61137869 | I23: =G23/E23 -> -0.17891153
B24: 22 | C24: 1325.3333 | D24: 2.6568793 | E24: 5.1114435 | F24: =(3600/$D$29) * (1 + ($C$29/(4*PI()*D24)) * ($B$34 + $C$34*(C24/1000) + $D$34*(C24/1000)^2)) * (1/$E$34 * (1 + D24^$F$34 * ($G$34 + $H$34/(C24/1000) + $I$34/((C24/1000)^2) + $J$34/((C24/1000)^3) + $K$34/((C24/1000)^4)))) -> 5.3580365 | G24: =E24-F24 -> -0.246593 | H24: =G24^2 -> 0.060808109 | I24: =G24/E24 -> -0.048243319
B25: 23* | C25: 1544.96 | D25: 2.9484293 | E25: 4.3124878 | F25: =(3600/$D$29) * (1 + ($C$29/(4*PI()*D25)) * ($B$34 + $C$34*(C25/1000) + $D$34*(C25/1000)^2)) * (1/$E$34 * (1 + D25^$F$34 * ($G$34 + $H$34/(C25/1000) + $I$34/((C25/1000)^2) + $J$34/((C25/1000)^3) + $K$34/((C25/1000)^4)))) -> 4.8672578 | G25: =E25-F25 -> -0.55476998 | H25: =G25^2 -> 0.30776973 | I25: =G25/E25 -> -0.12864268
I26: rmse
H27: =SUM(H3:H26) -> 4.8610927 | I27: =SQRT(H27/23) -> 0.4597302
C28: De | D28: Hg
C29: 211 | D29: 43000
B31: Goering Model
B33: A0 | C33: A1 | D33: A2 | E33: eito | F33: n | G33: B0 | H33: B1 | I33: B2 | J33: B3 | K33: B4
B34: 0.91571066 | C34: -0.001 | D34: 0.11503389 | E34: 0.93429408 | F34: 1.2034495 | G34: 0.56380413 | H34: 0.86130302 | I34: 0.6662834 | J34: 0.51390234 | K34: 0.51761119
